Workbook

Sheet LC Export Breakdown
B1: LC Export Breakdown | K1: LC Export Summary
K2: Metric | L2: Value
K3: Total LC Value (USD) | L3: =O18 -> 15049013
B4: Total value of LCs | D4: Total of Remaining Value | F4: Total of INVs | K4: Remaining Balance / Exposure (USD) | L4: =P18 -> 3994340.9
B5: =SUM(F14,F26,F43,F58,F72,F87,F101,F117,F138,F152,F167,F181,F195,F210,F228,F249,F263,F278,F292,F307,) -> 10931243 | D5: =SUM(B16,B30,B47,B62,B76,B91,B105,B121,B142,B156,B171,B185,B199,B214,B232,B253,B267,B282,B296,B311) -> 2391975 | F5: =SUM(F7,F21,F38,F53,F67,F82,F96,F112,F133,F147,F162,F176,F190,F205,F223,F244,F258,F273,F287,F302,) -> 47 | K5: Invoice Count | L5: =N18 -> 55
K6: LC Count | L6: =27 -> 27
A7: - | B7: LC # | C7: 1 | E7: INVOICES | F7: =SUBTOTAL(2,B18:B22) -> 1 | H7: =B8 -> Al Hashar Pharmacy Llc | K7: Exposure by Customer and Country
B8: Al Hashar Pharmacy Llc | H8: =CONCATENATE("LC Value USD LC #",B12) -> LC Value USD LC #2026/ILC/3378 | I8: =F12 -> 93458.11 | K8: Customer | L8: Country | M8: LC Count | N8: Invoice Count | O8: LC Value (USD) | P8: Remaining Balance / Exposure (USD) | Q8: % of Exposure
B9: 2000006 | H9: latest Date OS | I9: =D14 -> 31-Dec-2025 | K9: Al Hashar Pharmacy Llc | L9: Oman | M9: 9 | N9: =SUM(F7,F21,F38,F53,F162,F176,F190,F223,F302) -> 21 | O9: =SUM(F12,F26,F43,F58,F167,F181,F195,F228,F307) -> 3495538 | P9: =SUM(B16,B30,B47,B62,B171,B185,B199,B232,B311) -> 2319642.2 | Q9: =IFERROR(P9/$L$4,0) -> 0.58073215
B10: Oman | H10: Expiry date & place Saudi Arabia | I10: =E14 -> 46043 | K10: Al Hikma Fzco Iraq | L10: Iraq | M10: 4 | N10: =SUM(F67,F96,F205,F402) -> 12 | O10: =SUM(F72,F101,F210,F407) -> 3884477.4 | P10: =SUM(B76,B105,B214,B411) -> 459838.22 | Q10: =IFERROR(P10/$L$4,0) -> 0.11512243
B11: Advising | C11: Issuing | D11: Term | E11: Issuance | F11: Value (USD) | H11: Remaining Balance | I11: =B16 -> 0 | K11: El Hakeem For Importing Pharmaceutical | L11: Libya | M11: 2 | N11: =SUM(F273,F316) -> 1 | O11: =SUM(F278,F321) -> 297750.2 | P11: =SUM(B282,B325) -> 148875.35 | Q11: =IFERROR(P11/$L$4,0) -> 0.037271568
B12: 2026/ILC/3378 | C12: 26/BMLCU/40464 | D12: 180 Days From TCN | E12: 24-Oct-2025 | F12: 93458.11 | H12: ="We released# "& (C18) -> We released# 91187251 | I12: =D18 -> 93458.11 | K12: Kare Pharmaceutical Plc | L12: Ethiopia | M12: 3 | N12: =SUM(F147,F358,F388) -> 4 | O12: =SUM(F152,F363,F393) -> 1154039.9 | P12: =SUM(B156,B367,B397) -> 469381.79 | Q12: =IFERROR(P12/$L$4,0) -> 0.1175117
B13: Bank | C13: Bank | D13: LSD | E13: Expiry | F13: Total INV Value | H13: Remaining Balance after released New Order | I13: =B16 -> 0 | K13: Lanamed Pharmaceuticals Import | L13: Ethiopia | M13: 2 | N13: =SUM(F133,F330) -> 2 | O13: =SUM(F138,F335) -> 84619.99 | P13: =SUM(B142,B339) -> 6399.12 | Q13: =IFERROR(P13/$L$4,0) -> 0.0016020465
B14: BANK MUSCAT SA | C14: BANK MUSCAT OMAN | D14: 31-Dec-2025 | E14: 46043 | F14: =SUM(D18) -> 93458.11 | K14: Samt For Medical Supplies | L14: Libya | M14: 3 | N14: =SUM(F82,F287,F344) -> 4 | O14: =SUM(F87,F292,F349) -> 1253944.1 | P14: =SUM(B91,B296,B353) -> 0.95 | Q14: =IFERROR(P14/$L$4,0) -> 2.3783648e-07
B15: LC Remaining Value | K15: Tracon Trading Plc | L15: Ethiopia | M15: 1 | N15: =SUM(F258) -> 3 | O15: =SUM(F263) -> 563636.54 | P15: =SUM(B267) -> 15731.41 | Q15: =IFERROR(P15/$L$4,0) -> 0.0039384245
B16: =F12-F14 -> 0 | K16: Unicare Medical | L16: UAE | M16: 1 | N16: =SUM(F244) -> 0 | O16: =SUM(F249) -> 90596 | P16: =SUM(B253) -> 0 | Q16: =IFERROR(P16/$L$4,0) -> 0
B17: # | C17: INV | D17: Value | E17: Date | F17: Status | K17: Zenith Pharma | L17: Morocco | M17: 2 | N17: =SUM(F112,F372) -> 8 | O17: =SUM(F117,F377) -> 4224410.9 | P17: =SUM(B121,B381) -> 574471.9 | Q17: =IFERROR(P17/$L$4,0) -> 0.14382145
B18: 1 | C18: 91187251 | D18: 93458.11 | E18: 30-Jul-2026 | F18: Done | K18: Total | M18: =SUM(M9:M17) -> 27 | N18: =SUM(N9:N17) -> 55 | O18: =SUM(O9:O17) -> 15049013 | P18: =SUM(P9:P17) -> 3994340.9 | Q18: =SUM(Q9:Q17) -> 1
K20: Exposure by Country
A21: - | B21: LC # | C21: 2 | E21: INVOICES | F21: =SUBTOTAL(2,B32:B36) -> 4 | K21: Country | L21: LC Count | M21: Invoice Count | N21: LC Value (USD) | O21: Remaining Balance / Exposure (USD) | P21: % of Exposure
B22: Al Hashar Pharmacy Llc | K22: Ethiopia | L22: 6 | M22: =SUM(F133,F147,F258,F330,F358,F388) -> 9 | N22: =SUM(F138,F152,F263,F335,F363,F393) -> 1802296.5 | O22: =SUM(B142,B156,B267,B339,B367,B397) -> 491512.32 | P22: =IFERROR(O22/$L$4,0) -> 0.12305217
B23: 2000006 | K23: Iraq | L23: 4 | M23: =SUM(F67,F96,F205,F402) -> 12 | N23: =SUM(F72,F101,F210,F407) -> 3884477.4 | O23: =SUM(B76,B105,B214,B411) -> 459838.22 | P23: =IFERROR(O23/$L$4,0) -> 0.11512243
B24: Oman | K24: Libya | L24: 5 | M24: =SUM(F82,F273,F287,F316,F344) -> 5 | N24: =SUM(F87,F278,F292,F321,F349) -> 1551694.4 | O24: =SUM(B91,B282,B296,B325,B353) -> 148876.3 | P24: =IFERROR(O24/$L$4,0) -> 0.037271806
B25: Advising | C25: Issuing | D25: Term | E25: Issuance | F25: Value (USD) | K25: Morocco | L25: 2 | M25: =SUM(F112,F372) -> 8 | N25: =SUM(F117,F377) -> 4224410.9 | O25: =SUM(B121,B381) -> 574471.9 | P25: =IFERROR(O25/$L$4,0) -> 0.14382145
B26: 2026/ILC/3381 | C26: 26/BMLCU/40579 | D26: 180 Days From TCN | E26: 28-Jan-2026 | F26: 237831.61 | K26: Oman | L26: 9 | M26: =SUM(F7,F21,F38,F53,F162,F176,F190,F223,F302) -> 21 | N26: =SUM(F12,F26,F43,F58,F167,F181,F195,F228,F307) -> 3495538 | O26: =SUM(B16,B30,B47,B62,B171,B185,B199,B232,B311) -> 2319642.2 | P26: =IFERROR(O26/$L$4,0) -> 0.58073215
B27: Bank | C27: Bank | D27: LSD | E27: Expiry | F27: Total INV Value | H27: . | K27: UAE | L27: 1 | M27: =SUM(F244) -> 0 | N27: =SUM(F249) -> 90596 | O27: =SUM(B253) -> 0 | P27: =IFERROR(O27/$L$4,0) -> 0
B28: BANK MUSCAT SA | C28: BANK MUSCAT OMAN | D28: 15-Feb-2026 | E28: 46089 | F28: =SUM(D32:D35) -> 232613.67 | K28: Total | L28: =SUM(L22:L27) -> 27 | M28: =SUM(M22:M27) -> 55 | N28: =SUM(N22:N27) -> 15049013 | O28: =SUM(O22:O27) -> 3994340.9 | P28: =SUM(P22:P27) -> 1
B29: LC Remaining Value
B30: =F26-F28 -> 5217.94
B31: # | C31: INV | D31: Value | E31: Date | F31: Status
B32: 1 | C32: 91189924 | D32: 57415.67 | E32: 04-Aug-2026 | F32: Done
B33: 2 | C33: 91186097 | D33: 155195.44 | E33: 04-Aug-2026 | F33: Done
B34: 3 | C34: 91189919 | D34: 1993.6 | E34: 04-Aug-2026 | F34: Done
B35: 4 | C35: 91189901 | D35: 18008.96
A38: - | B38: LC # | C38: 3 | E38: INVOICES | F38: =SUBTOTAL(2,B49:B53) -> 2
B39: Al Hashar Pharmacy Llc
B40: 2000006
B41: Oman
B42: Advising | C42: Issuing | D42: Term | E42: Issuance | F42: Value (USD)
B43: 2026/ILC/3388 | C43: 26/BMLCU/40801 | D43: 180 Days From TCN | E43: 17-Feb-2026 | F43: 414745.85
...

Sheet Cust Data
B2: # | C2: Customer Name | D2: Country | E2: Customer Code
B3: 1 | C3: Alphamed | D3: UAE | E3: 2000005
B4: 2 | C4: Afaq Int. Marketing & Import Free Zone | D4: Iraq | E4: 2000584
B5: 3 | C5: Al Hashar Pharmacy (sgh) | D5: Oman | E5: 2000028
B6: 4 | C6: Al - Mojil Drug Co. | D6: Kuwait | E6: 2000000
B7: 5 | C7: Ali Abdulwahab Al-mutawa Commercial | D7: Kuwait | E7: 2000004
B8: 6 | C8: Munir Sukhtian Group Company | D8: Jordan | E8: 3555557
B9: 7 | C9: Roots Pharmaceutical Company | D9: Kuwait | E9: 2002042
B10: 8 | C10: Hamad Town Pharmacy | D10: Bahrain | E10: 2000009
B11: 9 | C11: Behzad Pharmacy | D11: Bahrain | E11: 2000002
B12: 10 | C12: Ebn Sina Medical | D12: Qatar | E12: 2001246
B13: 11 | C13: Dawakum Llc | D13: Oman | E13: 2001215
B14: 12 | C14: Green International Medical Co. Wll | D14: Bahrain | E14: 2001307
... B133: 131 | C133: Unicare Medical | D133: UAE | E133: 2002279

Sheet Banks Data
H1: our | J1: there
B2: # | C2: SA Banks | E2: # | F2: Global Banks | H2: ABC | J2: JUMHOURIA BANK
B3: 1 | C3: ABC | E3: 1 | F3: ALWAHA BANK | H3: ADIB | J3: INT. DEV. BANK
B4: 2 | C4: ADIB | E4: 2 | F4: AWASH BANK | H4: ANB | J4: GADAABANK
B5: 3 | C5: ANB | E5: 3 | F5: BANK DHOFAR | H5: ARAB BANK | J5: BANQUE POPULAIRE DE
B6: 4 | C6: ARAB BANK | E6: 4 | F6: BANK MUSCAT OMAN | H6: BANK MUSCAT SA | J6: BANK MUSCAT OMAN
B7: 5 | C7: BANK MUSCAT SA | E7: 5 | F7: BANQUE POPULAIRE DE | H7: BANK OF AFRICA | J7: BANK DHOFAR
B8: 6 | C8: BANK OF AFRICA | E8: 6 | F8: GADAABANK | H8: BILAD | J8: AWASH BANK
B9: 7 | C9: BILAD | E9: 7 | F9: INT. DEV. BANK | H9: BSF | J9: ALWAHA BANK
B10: 8 | C10: BSF | E10: 8 | F10: JUMHOURIA BANK | H10: ENBD
B11: 9 | C11: ENBD | H11: FAB
B12: 10 | C12: FAB | H12: GIB
B13: 11 | C13: GIB | H13: INMA
B14: 12 | C14: INMA | H14: NBI
B15: 13 | C15: NBI | H15: QNB
B16: 14 | C16: QNB | H16: RAJHI BANK
B17: 15 | C17: RAJHI BANK | H17: RIYAD BANK
B18: 16 | C18: RIYAD BANK | H18: SAB
B19: 17 | C19: SAB | H19: SNB
B20: 18 | C20: SNB

Sheet Payment Term
B3: # | C3: Payment Term
B4: 1 | C4: 180 Days From Shipment
B5: 2 | C5: 180 Days From Shipment Beneficiary Draft
B6: 3 | C6: 180 Days From TCN
B7: 4 | C7: 60 Calendar Days After Presentation Of Complied Documents
B8: 5 | C8: 90 Days From Dn
B9: 6 | C9: At Sight

Sheet Invoice Process Tracker
A1: CONSOLIDATED INVOICE PROCESS TRACKER | L1: INVOICE PROCESS CONTROL
A2: LC # | B2: Customer | C2: Invoice Number | D2: Value | E2: Pres. Date | F2: Status | G2: Coll. Date | H2: Due Date | I2: Tracking # | J2: Notes | K2: Next Action | L2: As of | M2: 46268
A3: 2026/ILC/3378 | B3: Al Hashar Pharmacy Llc | C3: 91187251 | D3: 93458.11 | F3: Accepted | H3: 46233 | K3: =IF(F3="Accepted",IF(G3="","Add collection date","Complete"),IF(E3="","Enter presentation date",IF(I3="","Add tracking #","Follow up"))) -> Add collection date
A4: 2026/ILC/3381 | B4: Al Hashar Pharmacy Llc | C4: 91189924 | D4: 57415.67 | F4: Accepted | H4: 46238 | K4: =IF(F4="Accepted",IF(G4="","Add collection date","Complete"),IF(E4="","Enter presentation date",IF(I4="","Add tracking #","Follow up"))) -> Add collection date | L4: Metric | M4: Value
A5: 2026/ILC/3381 | B5: Al Hashar Pharmacy Llc | C5: 91186097 | D5: 155195.44 | F5: Accepted | H5: 46238 | K5: =IF(F5="Accepted",IF(G5="","Add collection date","Complete"),IF(E5="","Enter presentation date",IF(I5="","Add tracking #","Follow up"))) -> Add collection date | L5: Total Invoices | M5: =COUNTA(C3:C62) -> 60
A6: 2026/ILC/3381 | B6: Al Hashar Pharmacy Llc | C6: 91189919 | D6: 1993.6 | F6: Accepted | H6: 46238 | K6: =IF(F6="Accepted",IF(G6="","Add collection date","Complete"),IF(E6="","Enter presentation date",IF(I6="","Add tracking #","Follow up"))) -> Add collection date | L6: Total Value | M6: =SUM(D3:D62) -> 11186702
A7: 2026/ILC/3381 | B7: Al Hashar Pharmacy Llc | C7: 91189901 | D7: 18008.96 | F7: Pending | J7: Not yet accepted | K7: =IF(F7="Accepted",IF(G7="","Add collection date","Complete"),IF(E7="","Enter presentation date",IF(I7="","Add tracking #","Follow up"))) -> Enter presentation date | L7: Accepted | M7: =COUNTIF(F3:F62,"Accepted") -> 11
A8: 2026/ILC/3388 | B8: Al Hashar Pharmacy Llc | C8: 91195705 | D8: 355645.85 | F8: Accepted | H8: 46259 | K8: =IF(F8="Accepted",IF(G8="","Add collection date","Complete"),IF(E8="","Enter presentation date",IF(I8="","Add tracking #","Follow up"))) -> Add collection date | L8: Pending | M8: =COUNTIF(F3:F62,"Pending") -> 49
A9: 2026/ILC/3388 | B9: Al Hashar Pharmacy Llc | C9: 91196156 | D9: 59100 | F9: Accepted | G9: 46259 | H9: 46259 | K9: =IF(F9="Accepted",IF(G9="","Add collection date","Complete"),IF(E9="","Enter presentation date",IF(I9="","Add tracking #","Follow up"))) -> Complete | L9: Missing Presentation Date | M9: =COUNTBLANK(E3:E62) -> 60
A10: 2026/ILC/3393 | B10: Al Hashar Pharmacy Llc | C10: 91197426 | D10: 172096.92 | F10: Pending | K10: =IF(F10="Accepted",IF(G10="","Add collection date","Complete"),IF(E10="","Enter presentation date",IF(I10="","Add tracking #","Follow up"))) -> Enter presentation date | L10: Missing Collection Date | M10: =COUNTBLANK(G3:G62) -> 59
A11: TF2605000007JEDX | B11: Al Hikma Fzco Iraq | C11: 91200826 | D11: 650451 | F11: Pending | K11: =IF(F11="Accepted",IF(G11="","Add collection date","Complete"),IF(E11="","Enter presentation date",IF(I11="","Add tracking #","Follow up"))) -> Enter presentation date | L11: Missing Tracking # | M11: =COUNTBLANK(I3:I62) -> 60
A12: TF2605000007JEDX | B12: Al Hikma Fzco Iraq | C12: 91206415 | D12: 100351.3 | F12: Pending | K12: =IF(F12="Accepted",IF(G12="","Add collection date","Complete"),IF(E12="","Enter presentation date",IF(I12="","Add tracking #","Follow up"))) -> Enter presentation date | L12: Pending and Overdue | M12: =COUNTIFS(F3:F62,"Pending",H3:H62,"<"&DATE(2026,9,3),H3:H62,"<>") -> 18
A13: ELC26BH00427 | B13: Samt For Medical Supplies | C13: 91199933 | D13: 200806.15 | F13: Pending | K13: =IF(F13="Accepted",IF(G13="","Add collection date","Complete"),IF(E13="","Enter presentation date",IF(I13="","Add tracking #","Follow up"))) -> Enter presentation date
A14: TF2608300001JEDX | B14: Al Hikma Fzco Iraq | C14: 91206417 | D14: 374620.58 | F14: Pending | K14: =IF(F14="Accepted",IF(G14="","Add collection date","Complete"),IF(E14="","Enter presentation date",IF(I14="","Add tracking #","Follow up"))) -> Enter presentation date | L14: Workflow
A15: TF2608300001JEDX | B15: Al Hikma Fzco Iraq | C15: 91213842 | D15: 286840.8 | F15: Pending | K15: =IF(F15="Accepted",IF(G15="","Add collection date","Complete"),IF(E15="","Enter presentation date",IF(I15="","Add tracking #","Follow up"))) -> Enter presentation date | L15: 1. Enter presentation date
A16: TF2608300001JEDX | B16: Al Hikma Fzco Iraq | C16: 91213847 | D16: 39033.9 | F16: Pending | K16: =IF(F16="Accepted",IF(G16="","Add collection date","Complete"),IF(E16="","Enter presentation date",IF(I16="","Add tracking #","Follow up"))) -> Enter presentation date | L16: 2. Update status
A17: EXWC020935 | B17: Zenith Pharma | C17: 91206606 | D17: 438144 | F17: Accepted | H17: 46304 | K17: =IF(F17="Accepted",IF(G17="","Add collection date","Complete"),IF(E17="","Enter presentation date",IF(I17="","Add tracking #","Follow up"))) -> Add collection date | L17: 3. Add collection date
A18: EXWC020935 | B18: Zenith Pharma | C18: 91206608 | D18: 310587.01 | F18: Accepted | H18: 46304 | K18: =IF(F18="Accepted",IF(G18="","Add collection date","Complete"),IF(E18="","Enter presentation date",IF(I18="","Add tracking #","Follow up"))) -> Add collection date | L18: 4. Record tracking number
A19: EXWC020935 | B19: Zenith Pharma | C19: 91206609 | D19: 37391.84 | F19: Accepted | H19: 46304 | K19: =IF(F19="Accepted",IF(G19="","Add collection date","Complete"),IF(E19="","Enter presentation date",IF(I19="","Add tracking #","Follow up"))) -> Add collection date | L19: 5. Review pending items weekly
A20: EXWC020935 | B20: Zenith Pharma | C20: 91213275 | D20: 84657.9 | F20: Pending | K20: =IF(F20="Accepted",IF(G20="","Add collection date","Complete"),IF(E20="","Enter presentation date",IF(I20="","Add tracking #","Follow up"))) -> Enter presentation date
A21: EXWC020935 | B21: Zenith Pharma | C21: 91213277 | D21: 592683.1 | F21: Pending | K21: =IF(F21="Accepted",IF(G21="","Add collection date","Complete"),IF(E21="","Enter presentation date",IF(I21="","Add tracking #","Follow up"))) -> Enter presentation date
A22: EXWC020935 | B22: Zenith Pharma | C22: 91228018 | D22: 555970.78 | F22: Pending | H22: 46198 | K22: =IF(F22="Accepted",IF(G22="","Add collection date","Complete"),IF(E22="","Enter presentation date",IF(I22="","Add tracking #","Follow up"))) -> Enter presentation date
A23: EXWC020935 | B23: Zenith Pharma | C23: 91228020 | D23: 700812.44 | F23: Pending | H23: 46198 | K23: =IF(F23="Accepted",IF(G23="","Add collection date","Complete"),IF(E23="","Enter presentation date",IF(I23="","Add tracking #","Follow up"))) -> Enter presentation date
A24: EXWC020935 | B24: Zenith Pharma | C24: 91228458 | D24: 161695.12 | F24: Pending | H24: 46198 | K24: =IF(F24="Accepted",IF(G24="","Add collection date","Complete"),IF(E24="","Enter presentation date",IF(I24="","Add tracking #","Follow up"))) -> Enter presentation date
A25: ELC/2026/00441QA | B25: Lanamed Pharmaceuticals Import | C25: 91206748 | D25: 46729 | F25: Pending | K25: =IF(F25="Accepted",IF(G25="","Add collection date","Complete"),IF(E25="","Enter presentation date",IF(I25="","Add tracking #","Follow up"))) -> Enter presentation date
A26: ELC/2026/00478QA | B26: Kare Pharmaceutical Plc | C26: 91205843 | D26: 389958.34 | F26: Pending | K26: =IF(F26="Accepted",IF(G26="","Add collection date","Complete"),IF(E26="","Enter presentation date",IF(I26="","Add tracking #","Follow up"))) -> Enter presentation date
A27: ELC/2026/00478QA | B27: Kare Pharmaceutical Plc | C27: 91214870 | D27: 85423.4 | F27: Pending | K27: =IF(F27="Accepted",IF(G27="","Add collection date","Complete"),IF(E27="","Enter presentation date",IF(I27="","Add tracking #","Follow up"))) -> Enter presentation date
A28: 2026/ILC/3407 | B28: Al Hashar Pharmacy Llc | C28: 91205473 | D28: 0 | F28: Pending | K28: =IF(F28="Accepted",IF(G28="","Add collection date","Complete"),IF(E28="","Enter presentation date",IF(I28="","Add tracking #","Follow up"))) -> Enter presentation date
A29: 2026/ILC/3417 | B29: Al Hashar Pharmacy Llc | C29: 91213468 | D29: 0 | F29: Pending | K29: =IF(F29="Accepted",IF(G29="","Add collection date","Complete"),IF(E29="","Enter presentation date",IF(I29="","Add tracking #","Follow up"))) -> Enter presentation date
A30: 2026/ILC/3405 | B30: Al Hashar Pharmacy Llc | C30: 91202373 | D30: 0 | F30: Pending | K30: =IF(F30="Accepted",IF(G30="","Add collection date","Complete"),IF(E30="","Enter presentation date",IF(I30="","Add tracking #","Follow up"))) -> Enter presentation date
A31: 2026/ILC/3405 | B31: Al Hashar Pharmacy Llc | C31: 91202528 | D31: 0 | F31: Pending | K31: =IF(F31="Accepted",IF(G31="","Add collection date","Complete"),IF(E31="","Enter presentation date",IF(I31="","Add tracking #","Follow up"))) -> Enter presentation date
A32: TF2612500004JEDX | B32: Al Hikma Fzco Iraq | C32: 91219417 | D32: 128390 | F32: Pending | K32: =IF(F32="Accepted",IF(G32="","Add collection date","Complete"),IF(E32="","Enter presentation date",IF(I32="","Add tracking #","Follow up"))) -> Enter presentation date
A33: TF2612500004JEDX | B33: Al Hikma Fzco Iraq | C33: 91219491 | D33: 47539.5 | F33: Pending | K33: =IF(F33="Accepted",IF(G33="","Add collection date","Complete"),IF(E33="","Enter presentation date",IF(I33="","Add tracking #","Follow up"))) -> Enter presentation date
A34: TF2612500004JEDX | B34: Al Hikma Fzco Iraq | C34: 91219571 | D34: 37818.2 | F34: Pending | K34: =IF(F34="Accepted",IF(G34="","Add collection date","Complete"),IF(E34="","Enter presentation date",IF(I34="","Add tracking #","Follow up"))) -> Enter presentation date
A35: TF2612500004JEDX | B35: Al Hikma Fzco Iraq | C35: 91226392 | D35: 308687.25 | F35: Pending | K35: =IF(F35="Accepted",IF(G35="","Add collection date","Complete"),IF(E35="","Enter presentation date",IF(I35="","Add tracking #","Follow up"))) -> Enter presentation date
A36: TF2612500004JEDX | B36: Al Hikma Fzco Iraq | C36: 91228981 | D36: 28988.08 | F36: Pending | H36: 46201 | K36: =IF(F36="Accepted",IF(G36="","Add collection date","Complete"),IF(E36="","Enter presentation date",IF(I36="","Add tracking #","Follow up"))) -> Enter presentation date
A37: TF2612500004JEDX | B37: Al Hikma Fzco Iraq | C37: 91226395 | D37: 215275.4 | F37: Pending | K37: =IF(F37="Accepted",IF(G37="","Add collection date","Complete"),IF(E37="","Enter presentation date",IF(I37="","Add tracking #","Follow up"))) -> Enter presentation date
A38: 2026/ILC/3432 | B38: Al Hashar Pharmacy Llc | C38: 91219680 | D38: 105721 | F38: Pending | H38: 46301 | K38: =IF(F38="Accepted",IF(G38="","Add collection date","Complete"),IF(E38="","Enter presentation date",IF(I38="","Add tracking #","Follow up"))) -> Enter presentation date
A39: 2026/ILC/3432 | B39: Al Hashar Pharmacy Llc | C39: 91219652 | D39: 657.72 | F39: Pending | H39: 46301 | K39: =IF(F39="Accepted",IF(G39="","Add collection date","Complete"),IF(E39="","Enter presentation date",IF(I39="","Add tracking #","Follow up"))) -> Enter presentation date
A40: 2026/ILC/3432 | B40: Al Hashar Pharmacy Llc | C40: 91219676 | D40: 33645.72 | F40: Pending | H40: 46301 | K40: =IF(F40="Accepted",IF(G40="","Add collection date","Complete"),IF(E40="","Enter presentation date",IF(I40="","Add tracking #","Follow up"))) -> Enter presentation date
...

Sheet Invoice Detail
A1: INVOICE DETAIL — FILL-IN REGISTER
A2: LC # | B2: Customer | C2: Invoice Number | D2: Invoice Value (USD) | E2: Presentation Date | F2: Status | G2: Collection Date | H2: Due Date | I2: Tracking # | J2: Notes
A3: 1/2026 | B3: AL HASHAR PHARMACY LLC | C3: 91187251 | D3: 93458.11 | F3: Accepted | H3: 46233
A4: 2/2026 | B4: AL HASHAR PHARMACY LLC | C4: 91189924 | D4: 57415.67 | F4: Accepted | H4: 46238
A5: 2/2026 | B5: AL HASHAR PHARMACY LLC | C5: 91186097 | D5: 155195.44 | F5: Accepted | H5: 46238
A6: 2/2026 | B6: AL HASHAR PHARMACY LLC | C6: 91189919 | D6: 1993.6 | F6: Accepted | H6: 46238
A7: 2/2026 | B7: AL HASHAR PHARMACY LLC | C7: 91189901 | D7: 18008.96 | F7: Pending | J7: Not yet accepted
A8: 3/2026 | B8: AL HASHAR PHARMACY LLC | C8: 91195705 | D8: 355645.85 | F8: Accepted | H8: 46259
A9: 3/2026 | B9: AL HASHAR PHARMACY LLC | C9: 91196156 | D9: 59100 | F9: Accepted | G9: 46259
A10: 4/2026 | B10: AL HASHAR PHARMACY LLC | C10: 91197426 | D10: 172096.92 | F10: Pending
A11: 5/2026 | B11: Al Hikma FZCO | C11: 91200826 | D11: 650451 | F11: Pending
A12: 5/2026 | B12: Al Hikma FZCO | C12: 91206415 | D12: 100351.3 | F12: Pending
A13: 6/2026 | B13: SMAT FOR MEDICAL SUPPLIES | C13: 91199933 | D13: 200806.15 | F13: Pending
A14: 7/2026 | B14: Al Hikma FZCO | C14: 91206417 | D14: 374620.58 | F14: Pending
A15: 7/2026 | B15: Al Hikma FZCO | C15: 91213842 | D15: 286840.8 | F15: Pending
A16: 7/2026 | B16: Al Hikma FZCO | C16: 91213847 | D16: 39033.9 | F16: Pending
A17: 9/2026 | B17: ZENITH PHARMA | C17: 91206606 | D17: 438144 | F17: Accepted | H17: 46304
A18: 9/2026 | B18: ZENITH PHARMA | C18: 91206608 | D18: 310587.01 | F18: Accepted | H18: 46304
A19: 9/2026 | B19: ZENITH PHARMA | C19: 91206609 | D19: 37391.84 | F19: Accepted | H19: 46304
A20: 9/2026 | B20: ZENITH PHARMA | C20: 91213275 | D20: 84657.9 | F20: Pending
A21: 9/2026 | B21: ZENITH PHARMA | C21: 91213277 | D21: 592683.1 | F21: Pending
A22: 10/2026 | B22: Lanamed Trading Plc | C22: 91206748 | D22: 46729 | F22: Pending
A23: 11/2026 | B23: Kare | C23: 91205843 | D23: 389958.34 | F23: Pending
A24: 11/2026 | B24: Kare | C24: 91214870 | D24: 85423.4 | F24: Pending
A25: TOTAL | D25: =SUM(D3:D24) -> 4550592.9
